<?xml version="1.0" ?>
<!-- =================================================================================== -->
<!-- |    This document was autogenerated by xacro from dog_v4.xacro                   | -->
<!-- |    EDITING THIS FILE BY HAND IS NOT RECOMMENDED                                 | -->
<!-- =================================================================================== -->
<robot name="dog">
  <!-- Defining the colors used in this robot -->
  <material name="Black">
    <color rgba="0 0 0 1"/>
  </material>
  <material name="White">
    <color rgba="1 1 1 1"/>
  </material>
  <material name="Blue">
    <color rgba="0 0 1 1"/>
  </material>
  <material name="Red">
    <color rgba="1 0 0 1"/>
  </material>
  <!-- base_link -->
  <link name="base_link">
    <visual>
      <origin rpy="0 0 0" xyz="0 0 0.044"/>
      <geometry>
        <box size="0.03 0.02 0.008"/>
      </geometry>
      <material name="White"/>
    </visual>
    <!-- <collision>
            <origin xyz="0 0 0" rpy="0 0 0" />
            <geometry>
                <box size="${body_link_length/10} ${body_link_width/10} ${body_link_height/10}" />
            </geometry>
        </collision> -->
  </link>
  <!-- body_link -->
  <link name="body_link">
    <visual>
      <origin rpy="0 0 0" xyz="0 0 0"/>
      <geometry>
        <box size="0.3 0.2 0.08"/>
      </geometry>
      <material name="White"/>
    </visual>
    <collision>
      <origin rpy="0 0 0" xyz="0 0 0"/>
      <geometry>
        <box size="0.15 0.2 0.08"/>
      </geometry>
    </collision>
    <inertial>
      <mass value="5"/>
      <inertia ixx="0.166667" ixy="0" ixz="0" iyy="0.166667" iyz="0" izz="0.166667"/>
    </inertial>
  </link>
  <link name="left_forward_leg_shoulder_link">
    <visual>
      <origin rpy="1.57 0 0" xyz="0 0 0"/>
      <geometry>
        <cylinder length="0.04" radius="0.04"/>
      </geometry>
      <material name="White"/>
    </visual>
    <collision>
      <origin rpy="1.57 0 0" xyz="0 0 0"/>
      <geometry>
        <cylinder length="0.02" radius="0.02"/>
      </geometry>
    </collision>
    <inertial>
      <mass value="0.68"/>
      <origin rpy="0 0 0" xyz="0 0 0"/>
      <inertia ixx="0.1" ixy="0.0" ixz="0.0" iyy="0.1" iyz="0.0" izz="0.2"/>
    </inertial>
    <!-- <xacro:inertial_matrix mass="0.68" /> -->
  </link>
  <link name="left_forward_leg_thigh_link">
    <visual>
      <origin rpy="0 0 0" xyz="0 0.1 0"/>
      <geometry>
        <box size="0.025 0.2 0.025"/>
      </geometry>
      <material name="Blue"/>
    </visual>
    <collision>
      <origin rpy="0 0 0" xyz="0 0.1 0"/>
      <geometry>
        <box size="0.0125 0.1 0.0125"/>
      </geometry>
    </collision>
    <inertial>
      <mass value="1"/>
      <inertia ixx="0.166667" ixy="0" ixz="0" iyy="0.166667" iyz="0" izz="0.166667"/>
    </inertial>
  </link>
  <link name="left_forward_leg_calf_link">
    <visual>
      <origin rpy="0 0 0" xyz="0 0.1 0"/>
      <geometry>
        <box size="0.025 0.2 0.025"/>
      </geometry>
      <material name="White"/>
    </visual>
    <collision>
      <origin rpy="0 0 0" xyz="0 0.1 0"/>
      <geometry>
        <box size="0.0125 0.1 0.0125"/>
      </geometry>
    </collision>
    <inertial>
      <mass value="0.166"/>
      <inertia ixx="0.166667" ixy="0" ixz="0" iyy="0.166667" iyz="0" izz="0.166667"/>
    </inertial>
  </link>
  <link name="left_forward_leg_feet_link">
    <visual>
      <origin rpy="0 0 0" xyz="0 0.1 0"/>
      <geometry>
        <sphere radius="0.017675"/>
      </geometry>
      <material name="Black"/>
    </visual>
    <collision>
      <origin rpy="0 0 0" xyz="0 0.1 0"/>
      <geometry>
        <sphere radius="0.017675"/>
      </geometry>
    </collision>
    <inertial>
      <mass value="0.06"/>
      <origin rpy="0 0 0" xyz="0 0 0"/>
      <inertia ixx="0.05" ixy="0" ixz="0" iyy="0.1" iyz="0" izz="0.1"/>
    </inertial>
  </link>
  <joint name="left_forward_leg_shoulder_joint" type="revolute">
    <origin rpy="-1.57 0 0" xyz="0 0.0325 0"/>
    <parent link="left_forward_leg_shoulder_link"/>
    <child link="left_forward_leg_thigh_link"/>
    <axis xyz="0 0 1"/>
    <limit effort="55" lower="-3.14159" upper="3.14159" velocity="52.4"/>
    <dynamics damping="0" friction="0"/>
  </joint>
  <joint name="left_forward_leg_keen_joint" type="revolute">
    <origin rpy="0 0 0" xyz="0 0.2 0"/>
    <parent link="left_forward_leg_thigh_link"/>
    <child link="left_forward_leg_calf_link"/>
    <axis xyz="0 0 1"/>
    <limit effort="55" lower="0.0" upper="2.6179916666666663" velocity="52.4"/>
    <dynamics damping="0" friction="0"/>
  </joint>
  <joint name="left_forward_leg_feet_joint" type="fixed">
    <origin rpy="0 0 0" xyz="0 0.1 0"/>
    <parent link="left_forward_leg_calf_link"/>
    <child link="left_forward_leg_feet_link"/>
    <axis xyz="0 0 1"/>
    <!-- <limit effort="300.0" lower="-${M_PI/2}" upper="${M_PI/2}" velocity="52.4" /> -->
    <!-- <dynamics damping="0" friction="0.1" /> -->
  </joint>
  <link name="left_back_leg_shoulder_link">
    <visual>
      <origin rpy="1.57 0 0" xyz="0 0 0"/>
      <geometry>
        <cylinder length="0.04" radius="0.04"/>
      </geometry>
      <material name="White"/>
    </visual>
    <collision>
      <origin rpy="1.57 0 0" xyz="0 0 0"/>
      <geometry>
        <cylinder length="0.02" radius="0.02"/>
      </geometry>
    </collision>
    <inertial>
      <mass value="0.68"/>
      <origin rpy="0 0 0" xyz="0 0 0"/>
      <inertia ixx="0.1" ixy="0.0" ixz="0.0" iyy="0.1" iyz="0.0" izz="0.2"/>
    </inertial>
    <!-- <xacro:inertial_matrix mass="0.68" /> -->
  </link>
  <link name="left_back_leg_thigh_link">
    <visual>
      <origin rpy="0 0 0" xyz="0 0.1 0"/>
      <geometry>
        <box size="0.025 0.2 0.025"/>
      </geometry>
      <material name="Blue"/>
    </visual>
    <collision>
      <origin rpy="0 0 0" xyz="0 0.1 0"/>
      <geometry>
        <box size="0.0125 0.1 0.0125"/>
      </geometry>
    </collision>
    <inertial>
      <mass value="1"/>
      <inertia ixx="0.166667" ixy="0" ixz="0" iyy="0.166667" iyz="0" izz="0.166667"/>
    </inertial>
  </link>
  <link name="left_back_leg_calf_link">
    <visual>
      <origin rpy="0 0 0" xyz="0 0.1 0"/>
      <geometry>
        <box size="0.025 0.2 0.025"/>
      </geometry>
      <material name="White"/>
    </visual>
    <collision>
      <origin rpy="0 0 0" xyz="0 0.1 0"/>
      <geometry>
        <box size="0.0125 0.1 0.0125"/>
      </geometry>
    </collision>
    <inertial>
      <mass value="0.166"/>
      <inertia ixx="0.166667" ixy="0" ixz="0" iyy="0.166667" iyz="0" izz="0.166667"/>
    </inertial>
  </link>
  <link name="left_back_leg_feet_link">
    <visual>
      <origin rpy="0 0 0" xyz="0 0.1 0"/>
      <geometry>
        <sphere radius="0.017675"/>
      </geometry>
      <material name="Black"/>
    </visual>
    <collision>
      <origin rpy="0 0 0" xyz="0 0.1 0"/>
      <geometry>
        <sphere radius="0.017675"/>
      </geometry>
    </collision>
    <inertial>
      <mass value="0.06"/>
      <origin rpy="0 0 0" xyz="0 0 0"/>
      <inertia ixx="0.05" ixy="0" ixz="0" iyy="0.1" iyz="0" izz="0.1"/>
    </inertial>
  </link>
  <joint name="left_back_leg_shoulder_joint" type="revolute">
    <origin rpy="-1.57 0 0" xyz="0 0.0325 0"/>
    <parent link="left_back_leg_shoulder_link"/>
    <child link="left_back_leg_thigh_link"/>
    <axis xyz="0 0 1"/>
    <limit effort="55" lower="-3.14159" upper="3.14159" velocity="52.4"/>
    <dynamics damping="0" friction="0"/>
  </joint>
  <joint name="left_back_leg_keen_joint" type="revolute">
    <origin rpy="0 0 0" xyz="0 0.2 0"/>
    <parent link="left_back_leg_thigh_link"/>
    <child link="left_back_leg_calf_link"/>
    <axis xyz="0 0 1"/>
    <limit effort="55" lower="0.0" upper="2.6179916666666663" velocity="52.4"/>
    <dynamics damping="0" friction="0"/>
  </joint>
  <joint name="left_back_leg_feet_joint" type="fixed">
    <origin rpy="0 0 0" xyz="0 0.1 0"/>
    <parent link="left_back_leg_calf_link"/>
    <child link="left_back_leg_feet_link"/>
    <axis xyz="0 0 1"/>
    <!-- <limit effort="300.0" lower="-${M_PI/2}" upper="${M_PI/2}" velocity="52.4" /> -->
    <!-- <dynamics damping="0" friction="0.1" /> -->
  </joint>
  <link name="right_forward_leg_shoulder_link">
    <visual>
      <origin rpy="1.57 0 0" xyz="0 0 0"/>
      <geometry>
        <cylinder length="0.04" radius="0.04"/>
      </geometry>
      <material name="White"/>
    </visual>
    <collision>
      <origin rpy="1.57 0 0" xyz="0 0 0"/>
      <geometry>
        <cylinder length="0.02" radius="0.02"/>
      </geometry>
    </collision>
    <inertial>
      <mass value="0.68"/>
      <origin rpy="0 0 0" xyz="0 0 0"/>
      <inertia ixx="0.1" ixy="0.0" ixz="0.0" iyy="0.1" iyz="0.0" izz="0.2"/>
    </inertial>
    <!-- <xacro:inertial_matrix mass="0.68" /> -->
  </link>
  <link name="right_forward_leg_thigh_link">
    <visual>
      <origin rpy="0 0 0" xyz="0 0.1 0"/>
      <geometry>
        <box size="0.025 0.2 0.025"/>
      </geometry>
      <material name="Blue"/>
    </visual>
    <collision>
      <origin rpy="0 0 0" xyz="0 0.1 0"/>
      <geometry>
        <box size="0.0125 0.1 0.0125"/>
      </geometry>
    </collision>
    <inertial>
      <mass value="1"/>
      <inertia ixx="0.166667" ixy="0" ixz="0" iyy="0.166667" iyz="0" izz="0.166667"/>
    </inertial>
  </link>
  <link name="right_forward_leg_calf_link">
    <visual>
      <origin rpy="0 0 0" xyz="0 0.1 0"/>
      <geometry>
        <box size="0.025 0.2 0.025"/>
      </geometry>
      <material name="White"/>
    </visual>
    <collision>
      <origin rpy="0 0 0" xyz="0 0.1 0"/>
      <geometry>
        <box size="0.0125 0.1 0.0125"/>
      </geometry>
    </collision>
    <inertial>
      <mass value="0.166"/>
      <inertia ixx="0.166667" ixy="0" ixz="0" iyy="0.166667" iyz="0" izz="0.166667"/>
    </inertial>
  </link>
  <link name="right_forward_leg_feet_link">
    <visual>
      <origin rpy="0 0 0" xyz="0 0.1 0"/>
      <geometry>
        <sphere radius="0.017675"/>
      </geometry>
      <material name="Black"/>
    </visual>
    <collision>
      <origin rpy="0 0 0" xyz="0 0.1 0"/>
      <geometry>
        <sphere radius="0.017675"/>
      </geometry>
    </collision>
    <inertial>
      <mass value="0.06"/>
      <origin rpy="0 0 0" xyz="0 0 0"/>
      <inertia ixx="0.05" ixy="0" ixz="0" iyy="0.1" iyz="0" izz="0.1"/>
    </inertial>
  </link>
  <joint name="right_forward_leg_shoulder_joint" type="revolute">
    <origin rpy="-1.57 0 0" xyz="0 -0.0325 0"/>
    <parent link="right_forward_leg_shoulder_link"/>
    <child link="right_forward_leg_thigh_link"/>
    <axis xyz="0 0 1"/>
    <limit effort="55" lower="-3.14159" upper="3.14159" velocity="52.4"/>
    <dynamics damping="0" friction="0"/>
  </joint>
  <joint name="right_forward_leg_keen_joint" type="revolute">
    <origin rpy="0 0 0" xyz="0 0.2 0"/>
    <parent link="right_forward_leg_thigh_link"/>
    <child link="right_forward_leg_calf_link"/>
    <axis xyz="0 0 1"/>
    <limit effort="55" lower="0.0" upper="2.6179916666666663" velocity="52.4"/>
    <dynamics damping="0" friction="0"/>
  </joint>
  <joint name="right_forward_leg_feet_joint" type="fixed">
    <origin rpy="0 0 0" xyz="0 0.1 0"/>
    <parent link="right_forward_leg_calf_link"/>
    <child link="right_forward_leg_feet_link"/>
    <axis xyz="0 0 1"/>
    <!-- <limit effort="300.0" lower="-${M_PI/2}" upper="${M_PI/2}" velocity="52.4" /> -->
    <!-- <dynamics damping="0" friction="0.1" /> -->
  </joint>
  <link name="right_back_leg_shoulder_link">
    <visual>
      <origin rpy="1.57 0 0" xyz="0 0 0"/>
      <geometry>
        <cylinder length="0.04" radius="0.04"/>
      </geometry>
      <material name="White"/>
    </visual>
    <collision>
      <origin rpy="1.57 0 0" xyz="0 0 0"/>
      <geometry>
        <cylinder length="0.02" radius="0.02"/>
      </geometry>
    </collision>
    <inertial>
      <mass value="0.68"/>
      <origin rpy="0 0 0" xyz="0 0 0"/>
      <inertia ixx="0.1" ixy="0.0" ixz="0.0" iyy="0.1" iyz="0.0" izz="0.2"/>
    </inertial>
    <!-- <xacro:inertial_matrix mass="0.68" /> -->
  </link>
  <link name="right_back_leg_thigh_link">
    <visual>
      <origin rpy="0 0 0" xyz="0 0.1 0"/>
      <geometry>
        <box size="0.025 0.2 0.025"/>
      </geometry>
      <material name="Blue"/>
    </visual>
    <collision>
      <origin rpy="0 0 0" xyz="0 0.1 0"/>
      <geometry>
        <box size="0.0125 0.1 0.0125"/>
      </geometry>
    </collision>
    <inertial>
      <mass value="1"/>
      <inertia ixx="0.166667" ixy="0" ixz="0" iyy="0.166667" iyz="0" izz="0.166667"/>
    </inertial>
  </link>
  <link name="right_back_leg_calf_link">
    <visual>
      <origin rpy="0 0 0" xyz="0 0.1 0"/>
      <geometry>
        <box size="0.025 0.2 0.025"/>
      </geometry>
      <material name="White"/>
    </visual>
    <collision>
      <origin rpy="0 0 0" xyz="0 0.1 0"/>
      <geometry>
        <box size="0.0125 0.1 0.0125"/>
      </geometry>
    </collision>
    <inertial>
      <mass value="0.166"/>
      <inertia ixx="0.166667" ixy="0" ixz="0" iyy="0.166667" iyz="0" izz="0.166667"/>
    </inertial>
  </link>
  <link name="right_back_leg_feet_link">
    <visual>
      <origin rpy="0 0 0" xyz="0 0.1 0"/>
      <geometry>
        <sphere radius="0.017675"/>
      </geometry>
      <material name="Black"/>
    </visual>
    <collision>
      <origin rpy="0 0 0" xyz="0 0.1 0"/>
      <geometry>
        <sphere radius="0.017675"/>
      </geometry>
    </collision>
    <inertial>
      <mass value="0.06"/>
      <origin rpy="0 0 0" xyz="0 0 0"/>
      <inertia ixx="0.05" ixy="0" ixz="0" iyy="0.1" iyz="0" izz="0.1"/>
    </inertial>
  </link>
  <joint name="right_back_leg_shoulder_joint" type="revolute">
    <origin rpy="-1.57 0 0" xyz="0 -0.0325 0"/>
    <parent link="right_back_leg_shoulder_link"/>
    <child link="right_back_leg_thigh_link"/>
    <axis xyz="0 0 1"/>
    <limit effort="55" lower="-3.14159" upper="3.14159" velocity="52.4"/>
    <dynamics damping="0" friction="0"/>
  </joint>
  <joint name="right_back_leg_keen_joint" type="revolute">
    <origin rpy="0 0 0" xyz="0 0.2 0"/>
    <parent link="right_back_leg_thigh_link"/>
    <child link="right_back_leg_calf_link"/>
    <axis xyz="0 0 1"/>
    <limit effort="55" lower="0.0" upper="2.6179916666666663" velocity="52.4"/>
    <dynamics damping="0" friction="0"/>
  </joint>
  <joint name="right_back_leg_feet_joint" type="fixed">
    <origin rpy="0 0 0" xyz="0 0.1 0"/>
    <parent link="right_back_leg_calf_link"/>
    <child link="right_back_leg_feet_link"/>
    <axis xyz="0 0 1"/>
    <!-- <limit effort="300.0" lower="-${M_PI/2}" upper="${M_PI/2}" velocity="52.4" /> -->
    <!-- <dynamics damping="0" friction="0.1" /> -->
  </joint>
  <!-- base_body_joint -->
  <joint name="base_body_joint" type="fixed">
    <origin rpy="0 0 0" xyz="0 0 0"/>
    <!--up: rpy="3.14 0 0" down: rpy="0 0 0"-->
    <parent link="base_link"/>
    <child link="body_link"/>
  </joint>
  <!-- leg_body_joint -->
  <joint name="left_forward_leg_body_joint" type="revolute">
    <origin rpy="0 0 0" xyz="0.19 0.09000000000000001 0"/>
    <parent link="body_link"/>
    <child link="left_forward_leg_shoulder_link"/>
    <axis xyz="1 0 0"/>
    <limit effort="20" lower="-1.570795" upper="1.570795" velocity="52.4"/>
    <dynamics damping="0" friction="0"/>
  </joint>
  <joint name="left_back_leg_body_joint" type="revolute">
    <origin rpy="0 0 0" xyz="-0.19 0.09000000000000001 0"/>
    <parent link="body_link"/>
    <child link="left_back_leg_shoulder_link"/>
    <axis xyz="1 0 0"/>
    <limit effort="20" lower="-1.570795" upper="1.570795" velocity="52.4"/>
    <dynamics damping="0" friction="0"/>
  </joint>
  <joint name="right_forward_leg_body_joint" type="revolute">
    <origin rpy="0 0 0" xyz="0.19 -0.09000000000000001 0"/>
    <parent link="body_link"/>
    <child link="right_forward_leg_shoulder_link"/>
    <axis xyz="1 0 0"/>
    <limit effort="20" lower="-1.570795" upper="1.570795" velocity="52.4"/>
    <dynamics damping="0" friction="0"/>
  </joint>
  <joint name="right_back_leg_body_joint" type="revolute">
    <origin rpy="0 0 0" xyz="-0.19 -0.09000000000000001 0"/>
    <parent link="body_link"/>
    <child link="right_back_leg_shoulder_link"/>
    <axis xyz="1 0 0"/>
    <limit effort="20" lower="-1.570795" upper="1.570795" velocity="52.4"/>
    <dynamics damping="0" friction="0"/>
  </joint>
  <!-- ros_control plugin -->
  <!-- <gazebo>
        <plugin name="gazebo_ros_control" filename="libgazebo_ros_control.so">
            <robotNamespace>/dog</robotNamespace>
        </plugin>
    </gazebo> -->
  <!-- Transmissions for ROS Control -->
  <!-- <xacro:macro name="transmission_block" params="joint_name">
        <transmission name="tran_${joint_name}">
            <type>transmission_interface/SimpleTransmission</type>
            <joint name="${joint_name}">
                <hardwareInterface>hardware_interface/PositionJointInterface</hardwareInterface>
            </joint>
            <actuator name="motor_${joint_name}">
                <hardwareInterface>hardware_interface/PositionJointInterface</hardwareInterface>
                <mechanicalReduction>1</mechanicalReduction>
            </actuator>
        </transmission>
    </xacro:macro> -->
  <!-- <xacro:transmission_block joint_name="left_forward_leg_body_joint"/>
    <xacro:transmission_block joint_name="left_forward_leg_keen_joint"/>

    <xacro:transmission_block joint_name="left_back_leg_body_joint"/>
    <xacro:transmission_block joint_name="left_back_leg_keen_joint"/>

    <xacro:transmission_block joint_name="right_forward_leg_body_joint"/>
    <xacro:transmission_block joint_name="right_forward_leg_keen_joint"/>

    <xacro:transmission_block joint_name="right_back_leg_body_joint"/>
    <xacro:transmission_block joint_name="right_back_leg_keen_joint"/> -->
</robot>
