<?xml version="1.0" ?>
<!-- =================================================================================== -->
<!-- |    This document was autogenerated by xacro from arm_dog.xacro                  | -->
<!-- |    EDITING THIS FILE BY HAND IS NOT RECOMMENDED                                 | -->
<!-- =================================================================================== -->
<robot name="arm_dog">
  <!-- Defining the colors used in this robot -->
  <material name="Black">
    <color rgba="0 0 0 1"/>
  </material>
  <material name="White">
    <color rgba="1 1 1 1"/>
  </material>
  <material name="Blue">
    <color rgba="0 0 1 1"/>
  </material>
  <material name="Red">
    <color rgba="1 0 0 1"/>
  </material>
  <!-- dog_base_link -->
  <link name="dog_base_link">
    <visual>
      <origin rpy="0 0 0" xyz="0 0 0.044"/>
      <geometry>
        <box size="0.03 0.02 0.008"/>
      </geometry>
      <material name="White"/>
    </visual>
  </link>
  <!-- body_link -->
  <link name="body_link">
    <visual>
      <origin rpy="0 0 0" xyz="0 0 0"/>
      <geometry>
        <box size="0.3 0.2 0.08"/>
      </geometry>
      <material name="White"/>
    </visual>
    <collision>
      <origin rpy="0 0 0" xyz="0 0 0"/>
      <geometry>
        <box size="0.15 0.2 0.08"/>
      </geometry>
    </collision>
    <inertial>
      <mass value="5"/>
      <inertia ixx="0.166667" ixy="0" ixz="0" iyy="0.166667" iyz="0" izz="0.166667"/>
    </inertial>
  </link>
  <link name="left_forward_leg_shoulder_link">
    <visual>
      <origin rpy="1.57 0 0" xyz="0 0 0"/>
      <geometry>
        <cylinder length="0.04" radius="0.04"/>
      </geometry>
      <material name="White"/>
    </visual>
    <collision>
      <origin rpy="1.57 0 0" xyz="0 0 0"/>
      <geometry>
        <cylinder length="0.02" radius="0.02"/>
      </geometry>
    </collision>
    <inertial>
      <mass value="0.68"/>
      <origin rpy="0 0 0" xyz="0 0 0"/>
      <inertia ixx="0.1" ixy="0.0" ixz="0.0" iyy="0.1" iyz="0.0" izz="0.2"/>
    </inertial>
    <!-- <xacro:inertial_matrix mass="0.68" /> -->
  </link>
  <link name="left_forward_leg_thigh_link">
    <visual>
      <origin rpy="0 0 0" xyz="0 0.1 0"/>
      <geometry>
        <box size="0.04 0.2 0.02"/>
      </geometry>
      <material name="Blue"/>
    </visual>
    <collision>
      <origin rpy="0 0 0" xyz="0 0.1 0"/>
      <geometry>
        <box size="0.02 0.1 0.01"/>
      </geometry>
    </collision>
    <inertial>
      <mass value="1"/>
      <inertia ixx="0.166667" ixy="0" ixz="0" iyy="0.166667" iyz="0" izz="0.166667"/>
    </inertial>
  </link>
  <link name="left_forward_leg_calf_link">
    <visual>
      <origin rpy="0 0 0" xyz="0 0.1 0"/>
      <geometry>
        <box size="0.02 0.2 0.02"/>
      </geometry>
      <material name="White"/>
    </visual>
    <collision>
      <origin rpy="0 0 0" xyz="0 0.1 0"/>
      <geometry>
        <box size="0.01 0.1 0.01"/>
      </geometry>
    </collision>
    <inertial>
      <mass value="0.166"/>
      <inertia ixx="0.166667" ixy="0" ixz="0" iyy="0.166667" iyz="0" izz="0.166667"/>
    </inertial>
  </link>
  <link name="left_forward_leg_feet_link">
    <visual>
      <origin rpy="0 0 0" xyz="0 0.1 0"/>
      <geometry>
        <sphere radius="0.017675"/>
      </geometry>
      <material name="Black"/>
    </visual>
    <collision>
      <origin rpy="0 0 0" xyz="0 0.1 0"/>
      <geometry>
        <sphere radius="0.017675"/>
      </geometry>
    </collision>
    <inertial>
      <mass value="0.06"/>
      <origin rpy="0 0 0" xyz="0 0 0"/>
      <inertia ixx="0.05" ixy="0" ixz="0" iyy="0.1" iyz="0" izz="0.1"/>
    </inertial>
  </link>
  <joint name="left_forward_leg_shoulder_joint" type="revolute">
    <origin rpy="-1.57 0 0" xyz="0 0.03 0"/>
    <parent link="left_forward_leg_shoulder_link"/>
    <child link="left_forward_leg_thigh_link"/>
    <axis xyz="0 0 1"/>
    <limit effort="55" lower="-3.14159" upper="3.14159" velocity="52.4"/>
    <dynamics damping="0" friction="0"/>
  </joint>
  <joint name="left_forward_leg_keen_joint" type="revolute">
    <origin rpy="0 0 0" xyz="0 0.2 0"/>
    <parent link="left_forward_leg_thigh_link"/>
    <child link="left_forward_leg_calf_link"/>
    <axis xyz="0 0 1"/>
    <limit effort="55" lower="0.0" upper="3.14159" velocity="52.4"/>
    <dynamics damping="0" friction="0"/>
  </joint>
  <joint name="left_forward_leg_feet_joint" type="fixed">
    <origin rpy="0 0 0" xyz="0 0.1 0"/>
    <parent link="left_forward_leg_calf_link"/>
    <child link="left_forward_leg_feet_link"/>
    <axis xyz="0 0 1"/>
  </joint>
  <link name="left_back_leg_shoulder_link">
    <visual>
      <origin rpy="1.57 0 0" xyz="0 0 0"/>
      <geometry>
        <cylinder length="0.04" radius="0.04"/>
      </geometry>
      <material name="White"/>
    </visual>
    <collision>
      <origin rpy="1.57 0 0" xyz="0 0 0"/>
      <geometry>
        <cylinder length="0.02" radius="0.02"/>
      </geometry>
    </collision>
    <inertial>
      <mass value="0.68"/>
      <origin rpy="0 0 0" xyz="0 0 0"/>
      <inertia ixx="0.1" ixy="0.0" ixz="0.0" iyy="0.1" iyz="0.0" izz="0.2"/>
    </inertial>
    <!-- <xacro:inertial_matrix mass="0.68" /> -->
  </link>
  <link name="left_back_leg_thigh_link">
    <visual>
      <origin rpy="0 0 0" xyz="0 0.1 0"/>
      <geometry>
        <box size="0.04 0.2 0.02"/>
      </geometry>
      <material name="Blue"/>
    </visual>
    <collision>
      <origin rpy="0 0 0" xyz="0 0.1 0"/>
      <geometry>
        <box size="0.02 0.1 0.01"/>
      </geometry>
    </collision>
    <inertial>
      <mass value="1"/>
      <inertia ixx="0.166667" ixy="0" ixz="0" iyy="0.166667" iyz="0" izz="0.166667"/>
    </inertial>
  </link>
  <link name="left_back_leg_calf_link">
    <visual>
      <origin rpy="0 0 0" xyz="0 0.1 0"/>
      <geometry>
        <box size="0.02 0.2 0.02"/>
      </geometry>
      <material name="White"/>
    </visual>
    <collision>
      <origin rpy="0 0 0" xyz="0 0.1 0"/>
      <geometry>
        <box size="0.01 0.1 0.01"/>
      </geometry>
    </collision>
    <inertial>
      <mass value="0.166"/>
      <inertia ixx="0.166667" ixy="0" ixz="0" iyy="0.166667" iyz="0" izz="0.166667"/>
    </inertial>
  </link>
  <link name="left_back_leg_feet_link">
    <visual>
      <origin rpy="0 0 0" xyz="0 0.1 0"/>
      <geometry>
        <sphere radius="0.017675"/>
      </geometry>
      <material name="Black"/>
    </visual>
    <collision>
      <origin rpy="0 0 0" xyz="0 0.1 0"/>
      <geometry>
        <sphere radius="0.017675"/>
      </geometry>
    </collision>
    <inertial>
      <mass value="0.06"/>
      <origin rpy="0 0 0" xyz="0 0 0"/>
      <inertia ixx="0.05" ixy="0" ixz="0" iyy="0.1" iyz="0" izz="0.1"/>
    </inertial>
  </link>
  <joint name="left_back_leg_shoulder_joint" type="revolute">
    <origin rpy="-1.57 0 0" xyz="0 0.03 0"/>
    <parent link="left_back_leg_shoulder_link"/>
    <child link="left_back_leg_thigh_link"/>
    <axis xyz="0 0 1"/>
    <limit effort="55" lower="-3.14159" upper="3.14159" velocity="52.4"/>
    <dynamics damping="0" friction="0"/>
  </joint>
  <joint name="left_back_leg_keen_joint" type="revolute">
    <origin rpy="0 0 0" xyz="0 0.2 0"/>
    <parent link="left_back_leg_thigh_link"/>
    <child link="left_back_leg_calf_link"/>
    <axis xyz="0 0 1"/>
    <limit effort="55" lower="0.0" upper="3.14159" velocity="52.4"/>
    <dynamics damping="0" friction="0"/>
  </joint>
  <joint name="left_back_leg_feet_joint" type="fixed">
    <origin rpy="0 0 0" xyz="0 0.1 0"/>
    <parent link="left_back_leg_calf_link"/>
    <child link="left_back_leg_feet_link"/>
    <axis xyz="0 0 1"/>
  </joint>
  <link name="right_forward_leg_shoulder_link">
    <visual>
      <origin rpy="1.57 0 0" xyz="0 0 0"/>
      <geometry>
        <cylinder length="0.04" radius="0.04"/>
      </geometry>
      <material name="White"/>
    </visual>
    <collision>
      <origin rpy="1.57 0 0" xyz="0 0 0"/>
      <geometry>
        <cylinder length="0.02" radius="0.02"/>
      </geometry>
    </collision>
    <inertial>
      <mass value="0.68"/>
      <origin rpy="0 0 0" xyz="0 0 0"/>
      <inertia ixx="0.1" ixy="0.0" ixz="0.0" iyy="0.1" iyz="0.0" izz="0.2"/>
    </inertial>
  </link>
  <link name="right_forward_leg_thigh_link">
    <visual>
      <origin rpy="0 0 0" xyz="0 0.1 0"/>
      <geometry>
        <box size="0.04 0.2 0.02"/>
      </geometry>
      <material name="Blue"/>
    </visual>
    <collision>
      <origin rpy="0 0 0" xyz="0 0.1 0"/>
      <geometry>
        <box size="0.02 0.1 0.01"/>
      </geometry>
    </collision>
    <inertial>
      <mass value="1"/>
      <inertia ixx="0.166667" ixy="0" ixz="0" iyy="0.166667" iyz="0" izz="0.166667"/>
    </inertial>
  </link>
  <link name="right_forward_leg_calf_link">
    <visual>
      <origin rpy="0 0 0" xyz="0 0.1 0"/>
      <geometry>
        <box size="0.02 0.2 0.02"/>
      </geometry>
      <material name="White"/>
    </visual>
    <collision>
      <origin rpy="0 0 0" xyz="0 0.1 0"/>
      <geometry>
        <box size="0.01 0.1 0.01"/>
      </geometry>
    </collision>
    <inertial>
      <mass value="0.166"/>
      <inertia ixx="0.166667" ixy="0" ixz="0" iyy="0.166667" iyz="0" izz="0.166667"/>
    </inertial>
  </link>
  <link name="right_forward_leg_feet_link">
    <visual>
      <origin rpy="0 0 0" xyz="0 0.1 0"/>
      <geometry>
        <sphere radius="0.017675"/>
      </geometry>
      <material name="Black"/>
    </visual>
    <collision>
      <origin rpy="0 0 0" xyz="0 0.1 0"/>
      <geometry>
        <sphere radius="0.017675"/>
      </geometry>
    </collision>
    <inertial>
      <mass value="0.06"/>
      <origin rpy="0 0 0" xyz="0 0 0"/>
      <inertia ixx="0.05" ixy="0" ixz="0" iyy="0.1" iyz="0" izz="0.1"/>
    </inertial>
  </link>
  <joint name="right_forward_leg_shoulder_joint" type="revolute">
    <origin rpy="-1.57 0 0" xyz="0 -0.03 0"/>
    <parent link="right_forward_leg_shoulder_link"/>
    <child link="right_forward_leg_thigh_link"/>
    <axis xyz="0 0 1"/>
    <limit effort="55" lower="-3.14159" upper="3.14159" velocity="52.4"/>
    <dynamics damping="0" friction="0"/>
  </joint>
  <joint name="right_forward_leg_keen_joint" type="revolute">
    <origin rpy="0 0 0" xyz="0 0.2 0"/>
    <parent link="right_forward_leg_thigh_link"/>
    <child link="right_forward_leg_calf_link"/>
    <axis xyz="0 0 1"/>
    <limit effort="55" lower="0.0" upper="3.14159" velocity="52.4"/>
    <dynamics damping="0" friction="0"/>
  </joint>
  <joint name="right_forward_leg_feet_joint" type="fixed">
    <origin rpy="0 0 0" xyz="0 0.1 0"/>
    <parent link="right_forward_leg_calf_link"/>
    <child link="right_forward_leg_feet_link"/>
    <axis xyz="0 0 1"/>
  </joint>
  <link name="right_back_leg_shoulder_link">
    <visual>
      <origin rpy="1.57 0 0" xyz="0 0 0"/>
      <geometry>
        <cylinder length="0.04" radius="0.04"/>
      </geometry>
      <material name="White"/>
    </visual>
    <collision>
      <origin rpy="1.57 0 0" xyz="0 0 0"/>
      <geometry>
        <cylinder length="0.02" radius="0.02"/>
      </geometry>
    </collision>
    <inertial>
      <mass value="0.68"/>
      <origin rpy="0 0 0" xyz="0 0 0"/>
      <inertia ixx="0.1" ixy="0.0" ixz="0.0" iyy="0.1" iyz="0.0" izz="0.2"/>
    </inertial>
  </link>
  <link name="right_back_leg_thigh_link">
    <visual>
      <origin rpy="0 0 0" xyz="0 0.1 0"/>
      <geometry>
        <box size="0.04 0.2 0.02"/>
      </geometry>
      <material name="Blue"/>
    </visual>
    <collision>
      <origin rpy="0 0 0" xyz="0 0.1 0"/>
      <geometry>
        <box size="0.02 0.1 0.01"/>
      </geometry>
    </collision>
    <inertial>
      <mass value="1"/>
      <inertia ixx="0.166667" ixy="0" ixz="0" iyy="0.166667" iyz="0" izz="0.166667"/>
    </inertial>
  </link>
  <link name="right_back_leg_calf_link">
    <visual>
      <origin rpy="0 0 0" xyz="0 0.1 0"/>
      <geometry>
        <box size="0.02 0.2 0.02"/>
      </geometry>
      <material name="White"/>
    </visual>
    <collision>
      <origin rpy="0 0 0" xyz="0 0.1 0"/>
      <geometry>
        <box size="0.01 0.1 0.01"/>
      </geometry>
    </collision>
    <inertial>
      <mass value="0.166"/>
      <inertia ixx="0.166667" ixy="0" ixz="0" iyy="0.166667" iyz="0" izz="0.166667"/>
    </inertial>
  </link>
  <link name="right_back_leg_feet_link">
    <visual>
      <origin rpy="0 0 0" xyz="0 0.1 0"/>
      <geometry>
        <sphere radius="0.017675"/>
      </geometry>
      <material name="Black"/>
    </visual>
    <collision>
      <origin rpy="0 0 0" xyz="0 0.1 0"/>
      <geometry>
        <sphere radius="0.017675"/>
      </geometry>
    </collision>
    <inertial>
      <mass value="0.06"/>
      <origin rpy="0 0 0" xyz="0 0 0"/>
      <inertia ixx="0.05" ixy="0" ixz="0" iyy="0.1" iyz="0" izz="0.1"/>
    </inertial>
  </link>
  <joint name="right_back_leg_shoulder_joint" type="revolute">
    <origin rpy="-1.57 0 0" xyz="0 -0.03 0"/>
    <parent link="right_back_leg_shoulder_link"/>
    <child link="right_back_leg_thigh_link"/>
    <axis xyz="0 0 1"/>
    <limit effort="55" lower="-3.14159" upper="3.14159" velocity="52.4"/>
    <dynamics damping="0" friction="0"/>
  </joint>
  <joint name="right_back_leg_keen_joint" type="revolute">
    <origin rpy="0 0 0" xyz="0 0.2 0"/>
    <parent link="right_back_leg_thigh_link"/>
    <child link="right_back_leg_calf_link"/>
    <axis xyz="0 0 1"/>
    <limit effort="55" lower="0.0" upper="3.14159" velocity="52.4"/>
    <dynamics damping="0" friction="0"/>
  </joint>
  <joint name="right_back_leg_feet_joint" type="fixed">
    <origin rpy="0 0 0" xyz="0 0.1 0"/>
    <parent link="right_back_leg_calf_link"/>
    <child link="right_back_leg_feet_link"/>
    <axis xyz="0 0 1"/>
  </joint>
  <!-- base_body_joint -->
  <joint name="base_body_joint" type="fixed">
    <origin rpy="0 0 0" xyz="0 0 0"/>
    <!--up: rpy="3.14 0 0" down: rpy="0 0 0"-->
    <parent link="dog_base_link"/>
    <child link="body_link"/>
  </joint>
  <!-- leg_body_joint -->
  <joint name="left_forward_leg_body_joint" type="revolute">
    <origin rpy="0 0 0" xyz="0.19 0.09000000000000001 0"/>
    <parent link="body_link"/>
    <child link="left_forward_leg_shoulder_link"/>
    <axis xyz="1 0 0"/>
    <limit effort="20" lower="-1.570795" upper="1.570795" velocity="52.4"/>
    <dynamics damping="0" friction="0"/>
  </joint>
  <joint name="left_back_leg_body_joint" type="revolute">
    <origin rpy="0 0 0" xyz="-0.19 0.09000000000000001 0"/>
    <parent link="body_link"/>
    <child link="left_back_leg_shoulder_link"/>
    <axis xyz="1 0 0"/>
    <limit effort="20" lower="-1.570795" upper="1.570795" velocity="52.4"/>
    <dynamics damping="0" friction="0"/>
  </joint>
  <joint name="right_forward_leg_body_joint" type="revolute">
    <origin rpy="0 0 0" xyz="0.19 -0.09000000000000001 0"/>
    <parent link="body_link"/>
    <child link="right_forward_leg_shoulder_link"/>
    <axis xyz="1 0 0"/>
    <limit effort="20" lower="-1.570795" upper="1.570795" velocity="52.4"/>
    <dynamics damping="0" friction="0"/>
  </joint>
  <joint name="right_back_leg_body_joint" type="revolute">
    <origin rpy="0 0 0" xyz="-0.19 -0.09000000000000001 0"/>
    <parent link="body_link"/>
    <child link="right_back_leg_shoulder_link"/>
    <axis xyz="1 0 0"/>
    <limit effort="20" lower="-1.570795" upper="1.570795" velocity="52.4"/>
    <dynamics damping="0" friction="0"/>
  </joint>
  <!-- ros_control plugin -->
  <gazebo>
    <plugin filename="libgazebo_ros_control.so" name="gazebo_ros_control">
      <robotNamespace>/dog</robotNamespace>
    </plugin>
  </gazebo>
  <transmission name="tran_dog">
    <type>transmission_interface/SimpleTransmission</type>
    <joint name="left_forward_leg_body_joint">
      <hardwareInterface>hardware_interface/PositionJointInterface</hardwareInterface>
    </joint>
    <actuator name="motor_dog">
      <hardwareInterface>hardware_interface/PositionJointInterface</hardwareInterface>
      <mechanicalReduction>1</mechanicalReduction>
    </actuator>
  </transmission>
  <transmission name="tran_dog">
    <type>transmission_interface/SimpleTransmission</type>
    <joint name="left_forward_leg_shoulder_joint">
      <hardwareInterface>hardware_interface/PositionJointInterface</hardwareInterface>
    </joint>
    <actuator name="motor_dog">
      <hardwareInterface>hardware_interface/PositionJointInterface</hardwareInterface>
      <mechanicalReduction>1</mechanicalReduction>
    </actuator>
  </transmission>
  <transmission name="tran_dog">
    <type>transmission_interface/SimpleTransmission</type>
    <joint name="left_forward_leg_keen_joint">
      <hardwareInterface>hardware_interface/PositionJointInterface</hardwareInterface>
    </joint>
    <actuator name="motor_dog">
      <hardwareInterface>hardware_interface/PositionJointInterface</hardwareInterface>
      <mechanicalReduction>1</mechanicalReduction>
    </actuator>
  </transmission>
  <transmission name="tran_dog">
    <type>transmission_interface/SimpleTransmission</type>
    <joint name="left_back_leg_body_joint">
      <hardwareInterface>hardware_interface/PositionJointInterface</hardwareInterface>
    </joint>
    <actuator name="motor_dog">
      <hardwareInterface>hardware_interface/PositionJointInterface</hardwareInterface>
      <mechanicalReduction>1</mechanicalReduction>
    </actuator>
  </transmission>
  <transmission name="tran_dog">
    <type>transmission_interface/SimpleTransmission</type>
    <joint name="left_back_leg_shoulder_joint">
      <hardwareInterface>hardware_interface/PositionJointInterface</hardwareInterface>
    </joint>
    <actuator name="motor_dog">
      <hardwareInterface>hardware_interface/PositionJointInterface</hardwareInterface>
      <mechanicalReduction>1</mechanicalReduction>
    </actuator>
  </transmission>
  <transmission name="tran_dog">
    <type>transmission_interface/SimpleTransmission</type>
    <joint name="left_back_leg_keen_joint">
      <hardwareInterface>hardware_interface/PositionJointInterface</hardwareInterface>
    </joint>
    <actuator name="motor_dog">
      <hardwareInterface>hardware_interface/PositionJointInterface</hardwareInterface>
      <mechanicalReduction>1</mechanicalReduction>
    </actuator>
  </transmission>
  <transmission name="tran_dog">
    <type>transmission_interface/SimpleTransmission</type>
    <joint name="right_forward_leg_body_joint">
      <hardwareInterface>hardware_interface/PositionJointInterface</hardwareInterface>
    </joint>
    <actuator name="motor_dog">
      <hardwareInterface>hardware_interface/PositionJointInterface</hardwareInterface>
      <mechanicalReduction>1</mechanicalReduction>
    </actuator>
  </transmission>
  <transmission name="tran_dog">
    <type>transmission_interface/SimpleTransmission</type>
    <joint name="right_forward_leg_shoulder_joint">
      <hardwareInterface>hardware_interface/PositionJointInterface</hardwareInterface>
    </joint>
    <actuator name="motor_dog">
      <hardwareInterface>hardware_interface/PositionJointInterface</hardwareInterface>
      <mechanicalReduction>1</mechanicalReduction>
    </actuator>
  </transmission>
  <transmission name="tran_dog">
    <type>transmission_interface/SimpleTransmission</type>
    <joint name="right_forward_leg_keen_joint">
      <hardwareInterface>hardware_interface/PositionJointInterface</hardwareInterface>
    </joint>
    <actuator name="motor_dog">
      <hardwareInterface>hardware_interface/PositionJointInterface</hardwareInterface>
      <mechanicalReduction>1</mechanicalReduction>
    </actuator>
  </transmission>
  <transmission name="tran_dog">
    <type>transmission_interface/SimpleTransmission</type>
    <joint name="right_back_leg_body_joint">
      <hardwareInterface>hardware_interface/PositionJointInterface</hardwareInterface>
    </joint>
    <actuator name="motor_dog">
      <hardwareInterface>hardware_interface/PositionJointInterface</hardwareInterface>
      <mechanicalReduction>1</mechanicalReduction>
    </actuator>
  </transmission>
  <transmission name="tran_dog">
    <type>transmission_interface/SimpleTransmission</type>
    <joint name="right_back_leg_shoulder_joint">
      <hardwareInterface>hardware_interface/PositionJointInterface</hardwareInterface>
    </joint>
    <actuator name="motor_dog">
      <hardwareInterface>hardware_interface/PositionJointInterface</hardwareInterface>
      <mechanicalReduction>1</mechanicalReduction>
    </actuator>
  </transmission>
  <transmission name="tran_dog">
    <type>transmission_interface/SimpleTransmission</type>
    <joint name="right_back_leg_keen_joint">
      <hardwareInterface>hardware_interface/PositionJointInterface</hardwareInterface>
    </joint>
    <actuator name="motor_dog">
      <hardwareInterface>hardware_interface/PositionJointInterface</hardwareInterface>
      <mechanicalReduction>1</mechanicalReduction>
    </actuator>
  </transmission>
  <!-- /////////////////////////// ARM ///////////////////////////////// -->
  <!-- /////////////////////////// ARM ///////////////////////////////// -->
  <!-- /////////////////////////// ARM ///////////////////////////////// -->
  <!-- <xacro:include filename="arm.xacro" /> -->
  <!-- Defining the colors used in this robot -->
  <material name="Black">
    <color rgba="0 0 0 1"/>
  </material>
  <material name="White">
    <color rgba="1 1 1 1"/>
  </material>
  <material name="Blue">
    <color rgba="0 0 1 1"/>
  </material>
  <material name="Red">
    <color rgba="1 0 0 1"/>
  </material>
  <!-- ///////////////////////////////////////   bottom_joint   ////////////////////////////////////////// -->
  <joint name="bottom_joint" type="fixed">
    <origin rpy="0 0 0" xyz="0 0 -0.025"/>
    <parent link="base_link"/>
    <child link="bottom_link"/>
  </joint>
  <link name="bottom_link">
    <visual>
      <origin rpy="0 0 0" xyz=" 0 0 0"/>
      <geometry>
        <box size="0.1 0.1 0.01"/>
      </geometry>
      <material name="Blue"/>
    </visual>
    <collision>
      <origin rpy="0 0 0" xyz=" 0 0 0"/>
      <geometry>
        <box size="0.1 0.1 0.01"/>
      </geometry>
    </collision>
    <inertial>
      <mass value="1000"/>
      <inertia ixx="1.0" ixy="0.0" ixz="0.0" iyy="0.5" iyz="0.0" izz="1.0"/>
    </inertial>
  </link>
  <!-- /////////////////////////////////////   BASE LINK    ////////////////////////////////////////////// -->
  <link name="base_link">
    <visual>
      <origin rpy="0 0 0" xyz="0 0 0"/>
      <geometry>
        <box size="0.1 0.1 0.04"/>
      </geometry>
      <material name="White"/>
    </visual>
    <collision>
      <origin rpy="0 0 0" xyz="0 0 0"/>
      <geometry>
        <box size="0.1 0.1 0.04"/>
      </geometry>
    </collision>
    <inertial>
      <mass value="1"/>
      <inertia ixx="1.0" ixy="0.0" ixz="0.0" iyy="0.5" iyz="0.0" izz="1.0"/>
    </inertial>
  </link>
  <joint name="joint1" type="revolute">
    <parent link="base_link"/>
    <child link="link1"/>
    <origin rpy="0 1.570795 0" xyz="0 0 0.02"/>
    <axis xyz="1 0 0"/>
    <limit effort="300" lower="-2.96" upper="2.96" velocity="1"/>
    <dynamics damping="50" friction="1"/>
  </joint>
  <!-- /////////////////////////////////////   LINK1  ////////////////////////////////////////////// -->
  <link name="link1">
    <visual>
      <origin rpy="0 1.570795 0" xyz="-0.075 0 0"/>
      <geometry>
        <cylinder length="0.15" radius="0.03"/>
      </geometry>
      <material name="Blue"/>
    </visual>
    <collision>
      <origin rpy="0 1.570795 0" xyz="-0.075 0 0"/>
      <geometry>
        <cylinder length="0.015" radius="0.003"/>
      </geometry>
    </collision>
    <inertial>
      <mass value="1"/>
      <inertia ixx="1.0" ixy="0.0" ixz="0.0" iyy="0.5" iyz="0.0" izz="1.0"/>
    </inertial>
  </link>
  <joint name="joint2" type="revolute">
    <parent link="link1"/>
    <child link="link2"/>
    <origin rpy="-1.570795 0 1.570795" xyz="-0.15 0 0.0"/>
    <axis xyz="1 0 0"/>
    <limit effort="300" lower="-2.35" upper="2.35" velocity="1"/>
    <dynamics damping="50" friction="1"/>
  </joint>
  <!-- ///////////////////////////////////////   LINK2  ////////////////////////////////////////////// -->
  <link name="link2">
    <visual>
      <origin rpy="0 0 0" xyz="0 0 0.1"/>
      <geometry>
        <cylinder length="0.2" radius="0.03"/>
      </geometry>
      <material name="White"/>
    </visual>
    <collision>
      <origin rpy="0 0 0" xyz="0 0 0.1"/>
      <geometry>
        <cylinder length="0.02" radius="0.003"/>
      </geometry>
    </collision>
    <inertial>
      <mass value="1"/>
      <inertia ixx="1.0" ixy="0.0" ixz="0.0" iyy="0.5" iyz="0.0" izz="1.0"/>
    </inertial>
  </link>
  <joint name="joint3" type="revolute">
    <parent link="link2"/>
    <child link="link3"/>
    <origin rpy="0 3.14159 0" xyz="0 0 0.2"/>
    <axis xyz="-1 0 0"/>
    <limit effort="300" lower="-2.62" upper="2.62" velocity="1"/>
    <dynamics damping="50" friction="1"/>
  </joint>
  <!-- /////////////////////////////////   LINK3  ///////////////////////////////////////////////////// -->
  <link name="link3">
    <visual>
      <origin rpy="0 0 0" xyz="0 0 -0.1"/>
      <geometry>
        <cylinder length="0.2" radius="0.03"/>
      </geometry>
      <material name="Blue"/>
    </visual>
    <collision>
      <origin rpy="0 0 0" xyz="0 0 -0.1"/>
      <geometry>
        <cylinder length="0.02" radius="0.003"/>
      </geometry>
    </collision>
    <inertial>
      <mass value="1"/>
      <inertia ixx="1.0" ixy="0.0" ixz="0.0" iyy="0.5" iyz="0.0" izz="1.0"/>
    </inertial>
  </link>
  <joint name="joint4" type="revolute">
    <parent link="link3"/>
    <child link="link4"/>
    <origin rpy="0 1.570795 3.14159" xyz="0.0 0.0 -0.2"/>
    <axis xyz="1 0 0"/>
    <limit effort="300" lower="-2.62" upper="2.62" velocity="1"/>
    <dynamics damping="50" friction="1"/>
  </joint>
  <!-- ///////////////////////////////////   LINK4  //////////////////////////////////////////////// -->
  <link name="link4">
    <visual>
      <origin rpy="0 1.570795 0" xyz="0.015 0 0"/>
      <geometry>
        <cylinder length="0.03" radius="0.025"/>
      </geometry>
      <material name="Black"/>
    </visual>
    <collision>
      <origin rpy="0 1.570795 0" xyz="0.015 0 0"/>
      <geometry>
        <cylinder length="0.03" radius="0.025"/>
      </geometry>
    </collision>
    <inertial>
      <mass value="1"/>
      <inertia ixx="1.0" ixy="0.0" ixz="0.0" iyy="0.5" iyz="0.0" izz="1.0"/>
    </inertial>
  </link>
  <joint name="joint5" type="revolute">
    <parent link="link4"/>
    <child link="link5"/>
    <origin rpy="0 1.570795 0" xyz="0.03 0.0 0.0"/>
    <axis xyz="-1 0 0"/>
    <limit effort="300" lower="-2.62" upper="2.62" velocity="1"/>
    <dynamics damping="50" friction="1"/>
  </joint>
  <!-- //////////////////////////////////   LINK5  ///////////////////////////////////////////////// -->
  <link name="link5">
    <visual>
      <origin rpy="0 0 0" xyz="0 0 0.015"/>
      <geometry>
        <cylinder length="0.06" radius="0.03"/>
      </geometry>
      <material name="White"/>
    </visual>
    <collision>
      <origin rpy="0 0 0" xyz="0 0 0.015 "/>
      <geometry>
        <cylinder length="0.06" radius="0.03"/>
      </geometry>
    </collision>
    <inertial>
      <mass value="1"/>
      <inertia ixx="1.0" ixy="0.0" ixz="0.0" iyy="0.5" iyz="0.0" izz="1.0"/>
    </inertial>
  </link>
  <joint name="joint6" type="revolute">
    <parent link="link5"/>
    <child link="link6"/>
    <origin rpy="4.712384999999999 -1.570795 0" xyz="0 0 0.03"/>
    <axis xyz="1 0 0"/>
    <limit effort="300" lower="-6.28" upper="6.28" velocity="1"/>
    <dynamics damping="50" friction="1"/>
  </joint>
  <!-- ////////////////////////////////   LINK6  ///////////////////////////////////////////////// -->
  <link name="link6">
    <visual>
      <origin rpy="0 1.570795 0" xyz="0.01 0 0 "/>
      <geometry>
        <cylinder length="0.02" radius="0.04"/>
      </geometry>
      <material name="Blue"/>
    </visual>
    <collision>
      <origin rpy="0 1.570795 0" xyz="0.01 0 0"/>
      <geometry>
        <cylinder length="0.02" radius="0.04"/>
      </geometry>
    </collision>
    <inertial>
      <mass value="1"/>
      <inertia ixx="1.0" ixy="0.0" ixz="0.0" iyy="0.5" iyz="0.0" izz="1.0"/>
    </inertial>
  </link>
  <joint name="finger_joint1" type="prismatic">
    <parent link="link6"/>
    <child link="gripper_finger_link1"/>
    <origin xyz="0.0 0 0"/>
    <axis xyz="0 1 0"/>
    <limit effort="100" lower="0" upper="0.015" velocity="0.05"/>
    <dynamics damping="50" friction="1"/>
  </joint>
  <!-- //////////////////////////////////////   gripper   ////////////////////////////////////////////// -->
  <!-- LEFT GRIPPER AFT LINK -->
  <link name="gripper_finger_link1">
    <visual>
      <origin xyz="0.05 -0.03 0"/>
      <geometry>
        <box size="0.06 0.01 0.01"/>
      </geometry>
      <material name="White"/>
    </visual>
    <collision>
      <origin xyz="0.05 -0.03 0"/>
      <geometry>
        <box size="0.06 0.01 0.01"/>
      </geometry>
    </collision>
    <contact_coefficients kd="1.0" kp="1.0" mu="1.0"/>
    <inertial>
      <mass value="1"/>
      <inertia ixx="1.0" ixy="0.0" ixz="0.0" iyy="0.5" iyz="0.0" izz="1.0"/>
    </inertial>
  </link>
  <joint name="finger_joint2" type="prismatic">
    <parent link="link6"/>
    <child link="gripper_finger_link2"/>
    <origin xyz="0.0 0 0"/>
    <axis xyz="0 -1 0"/>
    <limit effort="100" lower="0" upper="0.015" velocity="0.05"/>
    <dynamics damping="50" friction="1"/>
  </joint>
  <!-- RIGHT GRIPPER AFT LINK -->
  <link name="gripper_finger_link2">
    <visual>
      <origin xyz="0.05 0.03 0.0"/>
      <geometry>
        <box size="0.06 0.01 0.01"/>
      </geometry>
      <material name="White"/>
    </visual>
    <collision>
      <origin xyz="0.05 0.03 0"/>
      <geometry>
        <box size="0.06 0.01 0.01"/>
      </geometry>
    </collision>
    <inertial>
      <mass value="1"/>
      <inertia ixx="1.0" ixy="0.0" ixz="0.0" iyy="0.5" iyz="0.0" izz="1.0"/>
    </inertial>
  </link>
  <!-- Grasping frame -->
  <!-- <link name="grasping_frame"/>

    <joint name="grasping_frame_joint" type="fixed">
        <parent link="link6"/>
        <child link="grasping_frame"/>
        <origin xyz="0.08 0 0" rpy="0 0 0"/>
    </joint> -->
  <!-- connection_pos z -->
  <!-- mass -->
  <!-- camera link -->
  <link name="camera">
    <visual>
      <geometry>
        <box size="0.001 0.01 0.01"/>
      </geometry>
      <origin rpy="0.0 0.0 0.0" xyz="0.0 0.0 0.0"/>
      <material name="black"/>
    </visual>
    <collision>
      <geometry>
        <box size="0.001 0.01 0.01"/>
      </geometry>
      <origin rpy="0.0 0.0 0.0" xyz="0.0 0.0 0.0"/>
    </collision>
    <inertial>
      <mass value="0.01"/>
      <inertia ixx="8.416666666666667e-08" ixy="0" ixz="0" iyy="8.416666666666667e-08" iyz="0" izz="1.666666666666667e-07"/>
    </inertial>
  </link>
  <joint name="camera2base_link" type="fixed">
    <parent link="link6"/>
    <child link="camera"/>
    <origin rpy="3.1416 0.0 0.0" xyz="0.0205 0.0 0.0"/>
  </joint>
  <gazebo reference="camera">
    <material>Gazebo/Black</material>
  </gazebo>
  <!-- reference link -->
  <gazebo reference="camera">
    <!-- set type as camara -->
    <sensor name="rgb_camera" type="camera">
      <update_rate>60.0</update_rate>
      <!-- frequence -->
      <!-- properties of camera -->
      <camera name="rgb_camera">
        <horizontal_fov>1.3962634</horizontal_fov>
        <image>
          <width>1280</width>
          <height>720</height>
          <format>R8G8B8</format>
        </image>
        <clip>
          <near>0.02</near>
          <far>300</far>
        </clip>
        <noise>
          <type>gaussian</type>
          <mean>0.0</mean>
          <stddev>0.007</stddev>
        </noise>
      </camera>
      <!-- main plugin -->
      <plugin filename="libgazebo_ros_camera.so" name="camera_controller">
        <alwaysOn>true</alwaysOn>
        <updateRate>0.0</updateRate>
        <cameraName>/rgb_camera</cameraName>
        <imageTopicName>image_raw</imageTopicName>
        <cameraInfoTopicName>camera_info</cameraInfoTopicName>
        <frameName>camera</frameName>
        <hackBaseline>0.0</hackBaseline>
        <distortionK1>0.0</distortionK1>
        <distortionK2>0.0</distortionK2>
        <distortionK3>0.0</distortionK3>
        <distortionT1>0.0</distortionT1>
        <distortionT2>0.0</distortionT2>
      </plugin>
    </sensor>
  </gazebo>
  <!-- /////////////////////////////////   Gazebo   ////////////////////////////////////// -->
  <gazebo reference="bottom_link">
    <material>Gazebo/Black</material>
  </gazebo>
  <gazebo reference="base_link">
    <material>Gazebo/White</material>
  </gazebo>
  <gazebo reference="link1">
    <material>Gazebo/Blue</material>
  </gazebo>
  <gazebo reference="link2">
    <material>Gazebo/White</material>
  </gazebo>
  <gazebo reference="link3">
    <material>Gazebo/Blue</material>
  </gazebo>
  <gazebo reference="link4">
    <material>Gazebo/Black</material>
  </gazebo>
  <gazebo reference="link5">
    <material>Gazebo/White</material>
  </gazebo>
  <gazebo reference="link6">
    <material>Gazebo/Blue</material>
  </gazebo>
  <gazebo reference="gripper_finger_link1">
    <material>Gazebo/White</material>
  </gazebo>
  <gazebo reference="gripper_finger_link2">
    <material>Gazebo/White</material>
  </gazebo>
  <transmission name="tran1">
    <type>transmission_interface/SimpleTransmission</type>
    <joint name="joint1">
      <hardwareInterface>hardware_interface/PositionJointInterface</hardwareInterface>
    </joint>
    <actuator name="motor1">
      <hardwareInterface>hardware_interface/PositionJointInterface</hardwareInterface>
      <mechanicalReduction>1</mechanicalReduction>
    </actuator>
  </transmission>
  <transmission name="tran1">
    <type>transmission_interface/SimpleTransmission</type>
    <joint name="joint2">
      <hardwareInterface>hardware_interface/PositionJointInterface</hardwareInterface>
    </joint>
    <actuator name="motor1">
      <hardwareInterface>hardware_interface/PositionJointInterface</hardwareInterface>
      <mechanicalReduction>1</mechanicalReduction>
    </actuator>
  </transmission>
  <transmission name="tran1">
    <type>transmission_interface/SimpleTransmission</type>
    <joint name="joint3">
      <hardwareInterface>hardware_interface/PositionJointInterface</hardwareInterface>
    </joint>
    <actuator name="motor1">
      <hardwareInterface>hardware_interface/PositionJointInterface</hardwareInterface>
      <mechanicalReduction>1</mechanicalReduction>
    </actuator>
  </transmission>
  <transmission name="tran1">
    <type>transmission_interface/SimpleTransmission</type>
    <joint name="joint4">
      <hardwareInterface>hardware_interface/PositionJointInterface</hardwareInterface>
    </joint>
    <actuator name="motor1">
      <hardwareInterface>hardware_interface/PositionJointInterface</hardwareInterface>
      <mechanicalReduction>1</mechanicalReduction>
    </actuator>
  </transmission>
  <transmission name="tran1">
    <type>transmission_interface/SimpleTransmission</type>
    <joint name="joint5">
      <hardwareInterface>hardware_interface/PositionJointInterface</hardwareInterface>
    </joint>
    <actuator name="motor1">
      <hardwareInterface>hardware_interface/PositionJointInterface</hardwareInterface>
      <mechanicalReduction>1</mechanicalReduction>
    </actuator>
  </transmission>
  <transmission name="tran1">
    <type>transmission_interface/SimpleTransmission</type>
    <joint name="joint6">
      <hardwareInterface>hardware_interface/PositionJointInterface</hardwareInterface>
    </joint>
    <actuator name="motor1">
      <hardwareInterface>hardware_interface/PositionJointInterface</hardwareInterface>
      <mechanicalReduction>1</mechanicalReduction>
    </actuator>
  </transmission>
  <transmission name="tran1">
    <type>transmission_interface/SimpleTransmission</type>
    <joint name="finger_joint1">
      <hardwareInterface>hardware_interface/PositionJointInterface</hardwareInterface>
    </joint>
    <actuator name="motor1">
      <hardwareInterface>hardware_interface/PositionJointInterface</hardwareInterface>
      <mechanicalReduction>1</mechanicalReduction>
    </actuator>
  </transmission>
  <transmission name="tran1">
    <type>transmission_interface/SimpleTransmission</type>
    <joint name="finger_joint2">
      <hardwareInterface>hardware_interface/PositionJointInterface</hardwareInterface>
    </joint>
    <actuator name="motor1">
      <hardwareInterface>hardware_interface/PositionJointInterface</hardwareInterface>
      <mechanicalReduction>1</mechanicalReduction>
    </actuator>
  </transmission>
  <!-- ros_control plugin -->
  <gazebo>
    <plugin filename="libgazebo_ros_control.so" name="gazebo_ros_control">
      <robotNamespace>/arm</robotNamespace>
    </plugin>
  </gazebo>
  <gazebo>
    <plugin filename="libgazebo_grasp_fix.so" name="gazebo_grasp_fix">
      <arm>
        <arm_name>arm</arm_name>
        <palm_link> link6  </palm_link>
        <gripper_link> gripper_finger_link1 </gripper_link>
        <palm_link> link6  </palm_link>
        <gripper_link> gripper_finger_link2 </gripper_link>
      </arm>
      <forces_angle_tolerance>150</forces_angle_tolerance>
      <update_rate>130</update_rate>
      <grip_count_threshold>1</grip_count_threshold>
      <max_grip_count>8</max_grip_count>
      <release_tolerance>0.001</release_tolerance>
      <disable_collisions_on_attach>true</disable_collisions_on_attach>
      <contact_topic>__default_topic__</contact_topic>
    </plugin>
  </gazebo>
</robot>
